Workbook

Sheet sales
A1: Invoice ID | B1: Branch | C1: City | D1: Customer type | E1: Gender | F1: Product line | G1: Unit price | H1: Quantity | I1: Tax 5% | J1: Total | K1: cogs | L1: Date | M1: Time | N1: Payment | O1: Rating | P1: =SUM(J2:J5,K2:K4) | Q1: =PRODUCT(G2:H2,H3:H6) | R1: =MAX(I2:I13) | S1: =MIN(H2:H12) | T1: =AVERAGE(G2:G8,I2:I8) | U1: =COUNT(F2:F4,G2:G6) | V1: =COUNTA(G2:G5,F2:F3) | W1: =ROUNDUP(O2,0) | X1: =ROUNDDOWN(O2,0) | Y1: =ROUND(O2,2) | Z1: =POWER(X2,2) | AA1: =SQRT(Z2) | AB1: =LEN(Y2) | AC1: =SUBTOTAL(2,W2:Y2)
A2: 750-67-8428 | B2: A | C2: Trichy | D2: Member | E2: Female | F2: Health and beauty | G2: 74.69 | H2: 7 | I2: 26.1415 | J2: 548.9715 | K2: 522.83 | L2: 43586 | M2: 0.54722222 | N2: Ewallet | O2: 9.1373232 | P2: =SUM(J2:J5,K2:K4) -> 2382.305 | Q2: =PRODUCT(G2:H2,H3:H6) -> 1024746.8 | R2: =MAX(I2:I13) -> 36.78 | S2: =MIN(H2:H12) -> 2 | T2: =AVERAGE(G2:G8,I2:I8) -> 41.805143 | U2: =COUNT(F2:F4,G2:G6) -> 5 | V2: =COUNTA(G2:G5,F2:F3) -> 6 | W2: =ROUNDUP(O2,0) -> 10 | X2: =ROUNDDOWN(O2,0) -> 9 | Y2: =ROUND(O2,2) -> 9.14 | Z2: =POWER(X2,2) -> 81 | AA2: =SQRT(Z2) -> 9 | AB2: =LEN(Y2) -> 4 | AC2: =SUBTOTAL(2,W2:Y2) -> 3
A3: 226-31-3081 | B3: C | C3: Chennai | D3: Normal | E3: Female | F3: Electronic accessories | G3: 15.28 | H3: 5 | I3: 3.82 | J3: 80.22 | K3: 76.4 | L3: 43680 | M3: 0.43680556 | N3: Cash | O3: 9.6 | W3: =ROUNDUP(R2,0) -> 37 | X3: =ROUNDDOWN(R2,0) -> 36 | Y3: =ROUND(R2,1) -> 36.8
A4: 631-41-3108 | B4: A | C4: Trichy | D4: Normal | E4: Male | F4: Home and lifestyle | G4: 46.33 | H4: 7 | I4: 16.2155 | J4: 340.5255 | K4: 324.31 | L4: 43527 | M4: 0.55763889 | N4: Credit card | O4: 7.4 | V4: 1000.4343 | W4: =ROUNDDOWN(V4,0) -> 1000
A5: 123-19-1176 | B5: A | C5: Trichy | D5: Member | E5: Male | F5: Health and beauty | G5: 58.22 | H5: 8 | I5: 23.288 | J5: 489.048 | K5: 465.76 | L5: 43492 | M5: 0.85625 | N5: Ewallet | O5: 8.4
A6: 373-73-7910 | B6: A | C6: Trichy | D6: Normal | E6: Male | F6: Sports and travel | G6: 86.31 | H6: 7 | I6: 30.2085 | J6: 634.3785 | K6: 604.17 | L6: 43679 | M6: 0.44236111 | N6: Ewallet | O6: 5.3
A7: 699-14-3026 | B7: C | C7: Chennai | D7: Normal | E7: Male | F7: Electronic accessories | G7: 85.39 | H7: 7 | I7: 29.8865 | J7: 627.6165 | K7: 597.73 | L7: 43549 | M7: 0.77083333 | N7: Ewallet | O7: 4.1
A8: 355-53-5943 | B8: A | C8: Trichy | D8: Member | E8: Female | F8: Electronic accessories | G8: 68.84 | H8: 6 | I8: 20.652 | J8: 433.692 | K8: 413.04 | L8: 43521 | M8: 0.60833333 | N8: Ewallet | O8: 5.8
A9: 315-22-5665 | B9: C | C9: Chennai | D9: Normal | E9: Female | F9: Home and lifestyle | G9: 73.56 | H9: 10 | I9: 36.78 | J9: 772.38 | K9: 735.6 | L9: 43520 | M9: 0.48472222 | N9: Ewallet | O9: 8
A10: 665-32-9167 | B10: A | C10: Trichy | D10: Member | E10: Female | F10: Health and beauty | G10: 36.26 | H10: 2 | I10: 3.626 | J10: 76.146 | K10: 72.52 | L10: 43739 | M10: 0.71875 | N10: Credit card | O10: 7.2
A11: 692-92-5582 | B11: B | C11: karur | D11: Member | E11: Female | F11: Food and beverages | G11: 54.84 | H11: 3 | I11: 8.226 | J11: 172.746 | K11: 164.52 | L11: 43516 | M11: 0.56041667 | N11: Credit card | O11: 5.9
A12: 351-62-0822 | B12: B | C12: karur | D12: Member | E12: Female | F12: Fashion accessories | G12: 14.48 | H12: 4 | I12: 2.896 | J12: 60.816 | K12: 57.92 | L12: 43618 | M12: 0.75486111 | N12: Ewallet | O12: 4.5
A13: 529-56-3974 | B13: B | C13: karur | D13: Member | E13: Male | F13: Electronic accessories | G13: 25.51 | H13: 4 | I13: 5.102 | J13: 107.142 | K13: 102.04 | L13: 43711 | M13: 0.71041667 | N13: Cash | O13: 6.8
A14: 365-64-0515 | B14: A | C14: Trichy | D14: Normal | E14: Female | F14: Electronic accessories | G14: 46.95 | H14: 5 | I14: 11.7375 | J14: 246.4875 | K14: 234.75 | L14: 43801 | M14: 0.43402778 | N14: Ewallet | O14: 7.1
A15: 252-56-2699 | B15: A | C15: Trichy | D15: Normal | E15: Male | F15: Food and beverages | G15: 43.19 | H15: 10 | I15: 21.595 | J15: 453.495 | K15: 431.9 | L15: 43648 | M15: 0.7 | N15: Ewallet | O15: 8.2
A16: 829-34-3910 | B16: A | C16: Trichy | D16: Normal | E16: Female | F16: Health and beauty | G16: 71.38 | H16: 10 | I16: 35.69 | J16: 749.49 | K16: 713.8 | L16: 43553 | M16: 0.80625 | N16: Cash | O16: 5.7
... A4034: 849-09-3907 | B4034: A | C4034: Trichy | D4034: Member | E4034: Female | F4034: Fashion accessories | G4034: 88.34 | H4034: 8 | I4034: 30.919 | J4034: 649.08865 | K4034: 618.38 | L4034: 45706 | M4034: 0.56111111 | N4034: Cash | O4034: 6.8659917

Sheet If_Functions
A1: Sl No | B1: Roll No | C1: Student Name | D1: Tamil / Language | E1: English | F1: Maths | G1: Science / Social | H1: Total / Sum | I1: Average / % | J1: Grade / Remarks | K1: AND =AND(I2=51.25,G2=52) | L1: OR =OR(I2=51.25,G2=51) | M1: NOT =NOT(N2) | N1: If function =IF(I2<55,"C","No Grade") | O1: If function =IF(I2<55,"C",IF(AND(I2>55,I2<70),"B","A")) | P1: IFERROR =IFERROR(I3/0,"cannot divide by zero") | Q1: IFNA =IFNA(P2,"no value")
A2: 7 | B2: 7 | C2: Manoj Reddy | D2: 50 | E2: 55 | F2: 48 | G2: 52 | H2: 205 | I2: 51.25 | J2: C | K2: =AND(I2=51.25,G2=52) -> TRUE | L2: =OR(I2=51.25,G2=51) -> TRUE | M2: =NOT(L2) -> FALSE | N2: =IF(I2<55,"C","No Grade") -> C | O2: =IF(I2<55,"C",IF(AND(I2>55,I2<70),"B","A")) -> C | P2: =IFERROR(I2/O2,"You cannot divide number by any letter") -> You cannot divide number by any letter | Q2: =_xlfn.IFNA(P2,"no value") -> You cannot divide number by any letter
A3: 11 | B3: 11 | C3: Deepak Sharma | D3: 45 | E3: 50 | F3: 42 | G3: 48 | H3: 185 | I3: 46.25 | J3: C | K3: =AND(I3=51.25,G3=52) -> FALSE | L3: =OR(I3=51.25,G3=51) -> FALSE | M3: =NOT(L3) -> TRUE | N3: =IF(I3<55,"C","No Grade") -> C | O3: =IF(I3<55,"C",IF(AND(I3>55,I3<70),"B","A")) -> C | P3: =IFERROR(I3/0,"cannot divide by zero") -> cannot divide by zero | Q3: =_xlfn.IFNA(P3,"no value") -> cannot divide by zero
A4: 3 | B4: 3 | C4: Rahul Verma | D4: 65 | E4: 70 | F4: 55 | G4: 60 | H4: 250 | I4: 62.5 | J4: B | K4: =AND(I4=51.25,G4=52) -> FALSE | L4: =OR(I4=51.25,G4=51) -> FALSE | M4: =NOT(L4) -> TRUE | N4: =IF(I4<55,"C","No Grade") -> No Grade | O4: =IF(I4<55,"C",IF(AND(I4>55,I4<70),"B","A")) -> B | P4: #N/A | Q4: =_xlfn.IFNA(P4,"no value") -> no value
A5: 5 | B5: 5 | C5: Vikram Patil | D5: 58 | E5: 63 | F5: 60 | G5: 55 | H5: 236 | I5: 59 | J5: B | K5: =AND(I5=51.25,G5=52) -> FALSE | L5: =OR(I5=51.25,G5=51) -> FALSE | M5: =NOT(L5) -> TRUE | N5: =IF(I5<55,"C","No Grade") -> No Grade | O5: =IF(I5<55,"C",IF(AND(I5>55,I5<70),"B","A")) -> B | Q5: =_xlfn.IFNA(P5,"no value") -> 0
A6: 9 | B6: 9 | C6: Sanjay Mehta | D6: 67 | E6: 70 | F6: 72 | G6: 65 | H6: 274 | I6: 68.5 | J6: B | K6: =AND(I6=51.25,G6=52) -> FALSE | L6: =OR(I6=51.25,G6=51) -> FALSE | M6: =NOT(L6) -> TRUE | N6: =IF(I6<55,"C","No Grade") -> No Grade | O6: =IF(I6<55,"C",IF(AND(I6>55,I6<70),"B","A")) -> B | Q6: =_xlfn.IFNA(P6,"no value") -> 0
A7: 13 | B7: 13 | C7: Arjun Singh | D7: 58 | E7: 62 | F7: 65 | G7: 60 | H7: 245 | I7: 61.25 | J7: B | K7: =AND(I7=51.25,G7=52) -> FALSE | L7: =OR(I7=51.25,G7=51) -> FALSE | M7: =NOT(L7) -> TRUE | N7: =IF(I7<55,"C","No Grade") -> No Grade | O7: =IF(I7<55,"C",IF(AND(I7>55,I7<70),"B","A")) -> B | Q7: =_xlfn.IFNA(P7,"no value") -> 0
A8: 15 | B8: 15 | C8: Suresh Kumar | D8: 70 | E8: 68 | F8: 72 | G8: 65 | H8: 275 | I8: 68.75 | J8: B | K8: =AND(I8=51.25,G8=52) -> FALSE | L8: =OR(I8=51.25,G8=51) -> FALSE | M8: =NOT(L8) -> TRUE | N8: =IF(I8<55,"C","No Grade") -> No Grade | O8: =IF(I8<55,"C",IF(AND(I8>55,I8<70),"B","A")) -> B | Q8: =_xlfn.IFNA(P8,"no value") -> 0
A9: 17 | B9: 17 | C9: Rohit Chopra | D9: 60 | E9: 58 | F9: 55 | G9: 62 | H9: 235 | I9: 58.75 | J9: B | K9: =AND(I9=51.25,G9=52) -> FALSE | L9: =OR(I9=51.25,G9=51) -> FALSE | M9: =NOT(L9) -> TRUE | N9: =IF(I9<55,"C","No Grade") -> No Grade | O9: =IF(I9<55,"C",IF(AND(I9>55,I9<70),"B","A")) -> B | Q9: =_xlfn.IFNA(P9,"no value") -> 0
A10: 19 | B10: 19 | C10: Karan Kapoor | D10: 66 | E10: 70 | F10: 68 | G10: 64 | H10: 268 | I10: 67 | J10: B | K10: =AND(I10=51.25,G10=52) -> FALSE | L10: =OR(I10=51.25,G10=51) -> FALSE | M10: =NOT(L10) -> TRUE | N10: =IF(I10<55,"C","No Grade") -> No Grade | O10: =IF(I10<55,"C",IF(AND(I10>55,I10<70),"B","A")) -> B | Q10: =_xlfn.IFNA(P10,"no value") -> 0
A11: 1 | B11: 1 | C11: Aakash Kumar | D11: 85 | E11: 78 | F11: 92 | G11: 88 | H11: 343 | I11: 85.75 | J11: A | K11: =AND(I11=51.25,G11=52) -> FALSE | L11: =OR(I11=51.25,G11=51) -> FALSE | M11: =NOT(L11) -> TRUE | N11: =IF(I11<55,"C","No Grade") -> No Grade | O11: =IF(I11<55,"C",IF(AND(I11>55,I11<70),"B","A")) -> A | Q11: =_xlfn.IFNA(P11,"no value") -> 0
A12: 2 | B12: 2 | C12: Priya Singh | D12: 74 | E12: 81 | F12: 69 | G12: 72 | H12: 296 | I12: 74 | J12: A | K12: =AND(I12=51.25,G12=52) -> FALSE | L12: =OR(I12=51.25,G12=51) -> FALSE | M12: =NOT(L12) -> TRUE | N12: =IF(I12<55,"C","No Grade") -> No Grade | O12: =IF(I12<55,"C",IF(AND(I12>55,I12<70),"B","A")) -> A | Q12: =_xlfn.IFNA(P12,"no value") -> 0
A13: 4 | B13: 4 | C13: Sneha Sharma | D13: 90 | E13: 88 | F13: 95 | G13: 93 | H13: 366 | I13: 91.5 | J13: A | K13: =AND(I13=51.25,G13=52) -> FALSE | L13: =OR(I13=51.25,G13=51) -> FALSE | M13: =NOT(L13) -> TRUE | N13: =IF(I13<55,"C","No Grade") -> No Grade | O13: =IF(I13<55,"C",IF(AND(I13>55,I13<70),"B","A")) -> A | Q13: =_xlfn.IFNA(P13,"no value") -> 0
A14: 6 | B14: 6 | C14: Anjali Gupta | D14: 72 | E14: 75 | F14: 80 | G14: 78 | H14: 305 | I14: 76.25 | J14: A | K14: =AND(I14=51.25,G14=52) -> FALSE | L14: =OR(I14=51.25,G14=51) -> FALSE | M14: =NOT(L14) -> TRUE | N14: =IF(I14<55,"C","No Grade") -> No Grade | O14: =IF(I14<55,"C",IF(AND(I14>55,I14<70),"B","A")) -> A | Q14: =_xlfn.IFNA(P14,"no value") -> 0
A15: 8 | B15: 8 | C15: Pooja Desai | D15: 88 | E15: 92 | F15: 90 | G15: 89 | H15: 359 | I15: 89.75 | J15: A | K15: =AND(I15=51.25,G15=52) -> FALSE | L15: =OR(I15=51.25,G15=51) -> FALSE | M15: =NOT(L15) -> TRUE | N15: =IF(I15<55,"C","No Grade") -> No Grade | O15: =IF(I15<55,"C",IF(AND(I15>55,I15<70),"B","A")) -> A | Q15: =_xlfn.IFNA(P15,"no value") -> 0
A16: 10 | B16: 10 | C16: Ritu Joshi | D16: 80 | E16: 78 | F16: 85 | G16: 82 | H16: 325 | I16: 81.25 | J16: A | K16: =AND(I16=51.25,G16=52) -> FALSE | L16: =OR(I16=51.25,G16=51) -> FALSE | M16: =NOT(L16) -> TRUE | N16: =IF(I16<55,"C","No Grade") -> No Grade | O16: =IF(I16<55,"C",IF(AND(I16>55,I16<70),"B","A")) -> A | Q16: =_xlfn.IFNA(P16,"no value") -> 0
... A21: 20 | B21: 20 | C21: Priyanka Singh | D21: 89 | E21: 92 | F21: 95 | G21: 90 | H21: 366 | I21: 91.5 | J21: A | K21: =AND(I21=51.25,G21=52) -> FALSE | L21: =OR(I21=51.25,G21=51) -> FALSE | M21: =NOT(L21) -> TRUE | N21: =IF(I21<55,"C","No Grade") -> No Grade | O21: =IF(I21<55,"C",IF(AND(I21>55,I21<70),"B","A")) -> A | Q21: =_xlfn.IFNA(P21,"no value") -> 0

Sheet Dataset
A1: Invoice ID | B1: Branch | C1: City | D1: Customer type | E1: Gender | F1: Product line | G1: Unit price | H1: Quantity | I1: Tax 5% | J1: Total | K1: cogs | L1: Date | M1: Time | N1: Payment | O1: Rating
A2: 750-67-8428 | B2: A | C2: Trichy | D2: Member | E2: Female | F2: Health and beauty | G2: 74.69 | H2: 7 | I2: 26.1415 | J2: 548.9715 | K2: 522.83 | L2: 43586 | M2: 0.54722222 | N2: Ewallet | O2: 9.1373232
A3: 226-31-3081 | B3: C | C3: Chennai | D3: Normal | E3: Female | F3: Electronic accessories | G3: 15.28 | H3: 5 | I3: 3.82 | J3: 80.22 | K3: 76.4 | L3: 43680 | M3: 0.43680556 | N3: Cash | O3: 9.6
A4: 631-41-3108 | B4: A | C4: Trichy | D4: Normal | E4: Male | F4: Home and lifestyle | G4: 46.33 | H4: 7 | I4: 16.2155 | J4: 340.5255 | K4: 324.31 | L4: 43527 | M4: 0.55763889 | N4: Credit card | O4: 7.4
A5: 123-19-1176 | B5: A | C5: Trichy | D5: Member | E5: Male | F5: Health and beauty | G5: 58.22 | H5: 8 | I5: 23.288 | J5: 489.048 | K5: 465.76 | L5: 43492 | M5: 0.85625 | N5: Ewallet | O5: 8.4
A6: 373-73-7910 | B6: A | C6: Trichy | D6: Normal | E6: Male | F6: Sports and travel | G6: 86.31 | H6: 7 | I6: 30.2085 | J6: 634.3785 | K6: 604.17 | L6: 43679 | M6: 0.44236111 | N6: Ewallet | O6: 5.3
A7: 699-14-3026 | B7: C | C7: Chennai | D7: Normal | E7: Male | F7: Electronic accessories | G7: 85.39 | H7: 7 | I7: 29.8865 | J7: 627.6165 | K7: 597.73 | L7: 43549 | M7: 0.77083333 | N7: Ewallet | O7: 4.1
A8: 355-53-5943 | B8: A | C8: Trichy | D8: Member | E8: Female | F8: Electronic accessories | G8: 68.84 | H8: 6 | I8: 20.652 | J8: 433.692 | K8: 413.04 | L8: 43521 | M8: 0.60833333 | N8: Ewallet | O8: 5.8
A9: 315-22-5665 | B9: C | C9: Chennai | D9: Normal | E9: Female | F9: Home and lifestyle | G9: 73.56 | H9: 10 | I9: 36.78 | J9: 772.38 | K9: 735.6 | L9: 43520 | M9: 0.48472222 | N9: Ewallet | O9: 8
A10: 665-32-9167 | B10: A | C10: Trichy | D10: Member | E10: Female | F10: Health and beauty | G10: 36.26 | H10: 2 | I10: 3.626 | J10: 76.146 | K10: 72.52 | L10: 43739 | M10: 0.71875 | N10: Credit card | O10: 7.2
A11: 692-92-5582 | B11: B | C11: karur | D11: Member | E11: Female | F11: Food and beverages | G11: 54.84 | H11: 3 | I11: 8.226 | J11: 172.746 | K11: 164.52 | L11: 43516 | M11: 0.56041667 | N11: Credit card | O11: 5.9
A12: 351-62-0822 | B12: B | C12: karur | D12: Member | E12: Female | F12: Fashion accessories | G12: 14.48 | H12: 4 | I12: 2.896 | J12: 60.816 | K12: 57.92 | L12: 43618 | M12: 0.75486111 | N12: Ewallet | O12: 4.5
A13: 529-56-3974 | B13: B | C13: karur | D13: Member | E13: Male | F13: Electronic accessories | G13: 25.51 | H13: 4 | I13: 5.102 | J13: 107.142 | K13: 102.04 | L13: 43711 | M13: 0.71041667 | N13: Cash | O13: 6.8
... A4034: 849-09-3907 | B4034: A | C4034: Trichy | D4034: Member | E4034: Female | F4034: Fashion accessories | G4034: 88.34 | H4034: 8 | I4034: 30.919 | J4034: 649.08865 | K4034: 618.38 | L4034: 45706 | M4034: 0.56111111 | N4034: Cash | O4034: 6.8659917

Sheet sumif
J1: Overall product total
A2: sno | B2: =Dataset!E1 -> Gender | C2: =Dataset!F1 -> Product line | D2: =Dataset!J1 -> Total | J2: Product line | K2: =SUMIF(C:C,J2,D:D)
A3: sno | B3: =Dataset!E2 -> Female | C3: =Dataset!F2 -> Health and beauty | D3: =Dataset!J2 -> 548.9715 | J3: Health and beauty | K3: =SUMIF(C:C,J3,D:D) -> 204470.84
A4: sno | B4: =Dataset!E3 -> Female | C4: =Dataset!F3 -> Electronic accessories | D4: =Dataset!J3 -> 80.22 | J4: Electronic accessories | K4: =SUMIF(C:C,J4,D:D) -> 225535.74
A5: sno | B5: =Dataset!E4 -> Male | C5: =Dataset!F4 -> Home and lifestyle | D5: =Dataset!J4 -> 340.5255 | J5: Home and lifestyle | K5: =SUMIF(C:C,J5,D:D) -> 224162.13
A6: sno | B6: =Dataset!E5 -> Male | C6: =Dataset!F5 -> Health and beauty | D6: =Dataset!J5 -> 489.048 | J6: Sports and travel | K6: =SUMIF(C:C,J6,D:D) -> 229706.14
A7: sno | B7: =Dataset!E6 -> Male | C7: =Dataset!F6 -> Sports and travel | D7: =Dataset!J6 -> 634.3785 | J7: Food and beverages | K7: =SUMIF(C:C,J7,D:D) -> 234200.77
A8: sno | B8: =Dataset!E7 -> Male | C8: =Dataset!F7 -> Electronic accessories | D8: =Dataset!J7 -> 627.6165 | J8: Fashion accessories | K8: =SUMIF(C:C,J8,D:D) -> 227797.08
A9: sno | B9: =Dataset!E8 -> Female | C9: =Dataset!F8 -> Electronic accessories | D9: =Dataset!J8 -> 433.692
A10: sno | B10: =Dataset!E9 -> Female | C10: =Dataset!F9 -> Home and lifestyle | D10: =Dataset!J9 -> 772.38
A11: sno | B11: =Dataset!E10 -> Female | C11: =Dataset!F10 -> Health and beauty | D11: =Dataset!J10 -> 76.146
A12: sno | B12: =Dataset!E11 -> Female | C12: =Dataset!F11 -> Food and beverages | D12: =Dataset!J11 -> 172.746
A13: sno | B13: =Dataset!E12 -> Female | C13: =Dataset!F12 -> Fashion accessories | D13: =Dataset!J12 -> 60.816
A14: sno | B14: =Dataset!E13 -> Male | C14: =Dataset!F13 -> Electronic accessories | D14: =Dataset!J13 -> 107.142
A15: sno | B15: =Dataset!E14 -> Female | C15: =Dataset!F14 -> Electronic accessories | D15: =Dataset!J14 -> 246.4875
A16: sno | B16: =Dataset!E15 -> Male | C16: =Dataset!F15 -> Food and beverages | D16: =Dataset!J15 -> 453.495
A17: sno | B17: =Dataset!E16 -> Female | C17: =Dataset!F16 -> Health and beauty | D17: =Dataset!J16 -> 749.49
A18: sno | B18: =Dataset!E17 -> Female | C18: =Dataset!F17 -> Sports and travel | D18: =Dataset!J17 -> 590.436
A19: sno | B19: =Dataset!E18 -> Female | C19: =Dataset!F18 -> Health and beauty | D19: =Dataset!J18 -> 506.6355
A20: sno | B20: =Dataset!E19 -> Male | C20: =Dataset!F19 -> Sports and travel | D20: =Dataset!J19 -> 457.443
... A4035: sno | B4035: =Dataset!E4034 -> Female | C4035: =Dataset!F4034 -> Fashion accessories | D4035: =Dataset!J4034 -> 649.08865

Sheet Sheet1
A1: Invoice ID | B1: Branch | C1: City | D1: Customer type | E1: Gender | F1: Product line | G1: Unit price | H1: Quantity | I1: Tax 5% | J1: Total | K1: cogs | L1: Date | M1: Time | N1: Payment | O1: Rating | P1: level | T1: Product line | U1: TOTAL | V1: AVERAGE
A2: 300-71-4605 | C2: Chennai | D2: Member | E2: Male | F2: Electronic accessories | G2: 86.04 | H2: 5 | I2: 21.51 | J2: 451.71 | K2: 430.2 | L2: 43521 | M2: 0.475 | N2: Ewallet | O2: 4.8 | P2: low | T2: Electronic accessories | U2: =SUMIF(F:F,T2,J:J) -> 146566.17 | V2: =AVERAGEIF(F:F,T2,J:J) -> 215.53848 | W2: =COUNTIF(F:F,T2) -> 680
A3: 120-06-4233 | B3: C | C3: Chennai | D3: Normal | E3: Male | F3: Electronic accessories | G3: 30.61 | H3: 6 | I3: 9.183 | J3: 0 | K3: 183.66 | L3: 43802 | M3: 0.85833333 | N3: Cash | O3: 9.3 | P3: low | T3: Fashion accessories | U3: =SUMIF(F:F,T3,J:J) -> 135279.44 | V3: =AVERAGEIF(F:F,T3,J:J) -> 189.99921 | W3: =COUNTIF(F:F,T3) -> 712
A4: 841-35-6630 | B4: C | C4: Chennai | D4: Normal | E4: Female | F4: Electronic accessories | G4: 75.91 | H4: 6 | I4: 50000 | J4: 0 | K4: 455.46 | L4: 43711 | M4: 0.76458333 | N4: Cash | O4: 8.7 | P4: low | T4: Food and beverages | U4: =SUMIF(F:F,T4,J:J) -> 133759.83 | V4: =AVERAGEIF(F:F,T4,J:J) -> 192.18367 | W4: =COUNTIF(F:F,T4) -> 696
A5: 871-39-9221 | B5: C | C5: Chennai | D5: Normal | E5: Female | F5: Electronic accessories | G5: 12.45 | H5: 6 | I5: 3.735 | J5: 0 | K5: 74.7 | L5: 43710 | M5: 0.54930556 | N5: Cash | O5: 4.1 | P5: low | T5: Health and beauty | U5: =SUMIF(F:F,T5,J:J) -> 134587.82 | V5: =AVERAGEIF(F:F,T5,J:J) -> 221.36155 | W5: =COUNTIF(F:F,T5) -> 608
A6: 733-33-4967 | B6: C | C6: Chennai | D6: Normal | E6: Male | F6: Electronic accessories | G6: 20.85 | H6: 8 | I6: 8.34 | J6: 0 | K6: 166.8 | L6: 43527 | M6: 0.80347222 | N6: Cash | O6: 6.3 | P6: low | T6: Home and lifestyle | U6: =SUMIF(F:F,T6,J:J) -> 165881.26 | V6: =AVERAGEIF(F:F,T6,J:J) -> 259.18948 | W6: =COUNTIF(F:F,T6) -> 640
A7: 672-51-8681 | B7: C | C7: Chennai | D7: Member | E7: Female | F7: Electronic accessories | G7: 66.65 | H7: 9 | I7: 29.9925 | J7: 0 | K7: 599.85 | L7: 43556 | M7: 0.76319444 | N7: Credit card | O7: 9.7 | P7: low | T7: Sports and travel | U7: =SUMIF(F:F,T7,J:J) -> 162607.6 | V7: =AVERAGEIF(F:F,T7,J:J) -> 244.89097 | W7: =COUNTIF(F:F,T7) -> 664
A8: 380-94-4661 | B8: C | C8: Chennai | D8: Member | E8: Male | F8: Electronic accessories | G8: 65.94 | H8: 4 | I8: 13.188 | J8: 0 | K8: 263.76 | L8: 43648 | M8: 0.54513889 | N8: Credit card | O8: 6.9 | P8: low
A9: 211-05-0490 | B9: C | C9: Chennai | D9: Member | E9: Female | F9: Electronic accessories | G9: 51.92 | H9: 5 | I9: 12.98 | J9: 0 | K9: 259.6 | L9: 43527 | M9: 0.57083333 | N9: Cash | O9: 7.5 | P9: low
A10: 233-34-0817 | B10: C | C10: Chennai | D10: Member | E10: Female | F10: Electronic accessories | G10: 98.84 | H10: 1 | I10: 4.942 | J10: 0 | K10: 98.84 | L10: 43511 | M10: 0.47291667 | N10: Cash | O10: 8.4 | P10: low
A11: 556-97-7101 | B11: C | C11: Chennai | D11: Normal | E11: Female | F11: Electronic accessories | G11: 63.22 | H11: 2 | I11: 6.322 | J11: 0 | K11: 126.44 | L11: 43466 | M11: 0.66041667 | N11: Cash | O11: 8.5 | P11: low
A12: 219-61-4139 | B12: C | C12: Chennai | D12: Normal | E12: Male | F12: Electronic accessories | G12: 83.08 | H12: 1 | I12: 4.154 | J12: 0 | K12: 83.08 | L12: 43488 | M12: 0.71944444 | N12: Ewallet | O12: 6.4 | P12: low
A13: 273-84-2164 | B13: C | C13: Chennai | D13: Member | E13: Male | F13: Electronic accessories | G13: 12.05 | H13: 5 | I13: 3.0125 | J13: 0 | K13: 60.25 | L13: 43512 | M13: 0.66180556 | N13: Ewallet | O13: 5.5 | P13: low | T13: Product line | U13: Female | V13: Male | W13: TOTAL
A14: 740-11-5257 | B14: C | C14: Chennai | D14: Normal | E14: Male | F14: Electronic accessories | G14: 24.74 | H14: 10 | I14: 12.37 | J14: 0 | K14: 247.4 | L14: 43520 | M14: 0.69722222 | N14: Cash | O14: 7.1 | P14: low | T14: Electronic accessories | U14: =SUMIFS(J:J,F:F,T14,E:E,U13) -> 74910.188 | V14: =SUMIFS(J:J,E:E,V13,F:F,T14) -> 71655.979 | W14: =SUMIF(F:F,T14,J:J) -> 146566.17
A15: 183-21-3799 | B15: C | C15: Chennai | D15: Normal | E15: Female | F15: Electronic accessories | G15: 77.63 | H15: 9 | I15: 34.9335 | J15: 0 | K15: 698.67 | L15: 43515 | M15: 0.63472222 | N15: Ewallet | O15: 7.2 | P15: low | T15: Fashion accessories | W15: =SUMIF(F:F,T15,J:J) -> 135279.44
A16: 377-79-7592 | B16: C | C16: Chennai | D16: Member | E16: Female | F16: Electronic accessories | G16: 44.84 | H16: 9 | I16: 20.178 | J16: 0 | K16: 403.56 | L16: 43479 | M16: 0.58333333 | N16: Credit card | O16: 7.5 | P16: low | T16: Food and beverages | W16: =SUMIF(F:F,T16,J:J) -> 133759.83
A17: 151-27-8496 | B17: C | C17: Chennai | D17: Normal | E17: Female | F17: Electronic accessories | G17: 56.13 | H17: 4 | I17: 11.226 | J17: 0 | K17: 224.52 | L17: 43484 | M17: 0.48819444 | N17: Ewallet | O17: 8.6 | P17: low | T17: Health and beauty | W17: =SUMIF(F:F,T17,J:J) -> 134587.82
A18: 717-96-4189 | B18: C | C18: Chennai | D18: Normal | E18: Female | F18: Electronic accessories | G18: 35.49 | H18: 6 | I18: 10.647 | J18: 0 | K18: 212.94 | L18: 43498 | M18: 0.52777778 | N18: Cash | O18: 4.1 | P18: low | T18: Home and lifestyle | W18: =SUMIF(F:F,T18,J:J) -> 165881.26
A19: 267-62-7380 | B19: C | C19: Chennai | D19: Member | E19: Male | F19: Electronic accessories | G19: 82.34 | H19: 10 | I19: 41.17 | J19: 0 | K19: 823.4 | L19: 43553 | M19: 0.8 | N19: Ewallet | O19: 4.3 | P19: low | T19: Sports and travel | W19: =SUMIF(F:F,T19,J:J) -> 162607.6
A20: 699-14-3026 | B20: C | C20: Chennai | D20: Normal | E20: Male | F20: Electronic accessories | G20: 85.39 | H20: 6 | I20: 29.8865 | J20: 0 | K20: 597.73 | L20: 44645 | M20: 0.77083333 | N20: Ewallet | O20: 3.9647259 | P20: low
A21: 871-39-9221 | B21: C | C21: Chennai | D21: Normal | E21: Female | F21: Electronic accessories | G21: 12.45 | H21: 5 | I21: 3.735 | J21: 0 | K21: 74.7 | L21: 44806 | M21: 0.54930556 | N21: Cash | O21: 3.9647259 | P21: low
A22: 733-33-4967 | B22: C | C22: Chennai | D22: Normal | E22: Male | F22: Electronic accessories | G22: 20.85 | H22: 7 | I22: 8.34 | J22: 0 | K22: 166.8 | L22: 44623 | M22: 0.80347222 | N22: Cash | O22: 6.0921397 | P22: low
A23: 211-05-0490 | B23: C | C23: Chennai | D23: Member | E23: Female | F23: Electronic accessories | G23: 51.92 | H23: 4 | I23: 12.98 | J23: 0 | K23: 259.6 | L23: 44623 | M23: 0.57083333 | N23: Cash | O23: 7.2525473 | P23: low
A24: 727-75-6477 | B24: C | C24: Chennai | D24: Normal | E24: Male | F24: Electronic accessories | G24: 28.84 | H24: 4 | I24: 5.768 | J24: 0 | K24: 115.36 | L24: 44649 | M24: 0.61388889 | N24: Cash | O24: 6.1888404 | P24: low
A25: 227-07-4446 | B25: C | C25: Chennai | D25: Member | E25: Female | F25: Electronic accessories | G25: 78.13 | H25: 9 | I25: 39.065 | J25: 0 | K25: 781.3 | L25: 44836 | M25: 0.86875 | N25: Cash | O25: 4.2548277 | P25: low
A26: 320-49-6392 | B26: C | C26: Chennai | D26: Normal | E26: Female | F26: Electronic accessories | G26: 30.24 | H26: 1 | I26: 1.512 | J26: 0 | K26: 30.24 | L26: 44654 | M26: 0.65555556 | N26: Cash | O26: 8.122853 | P26: low
A27: 122-61-9553 | B27: C | C27: Chennai | D27: Normal | E27: Female | F27: Electronic accessories | G27: 51.32 | H27: 8 | I27: 23.094 | J27: 0 | K27: 461.88 | L27: 44634 | M27: 0.81458333 | N27: Cash | O27: 5.4152353 | P27: low
A28: 598-47-9715 | B28: C | C28: Chennai | D28: Normal | E28: Male | F28: Electronic accessories | G28: 84.07 | H28: 4 | I28: 16.814 | J28: 0 | K28: 336.28 | L28: 44745 | M28: 0.70416667 | N28: Ewallet | O28: 4.2548277 | P28: low
A29: 399-69-4630 | B29: C | C29: Chennai | D29: Normal | E29: Male | F29: Electronic accessories | G29: 22.21 | H29: 5 | I29: 6.663 | J29: 0 | K29: 133.26 | L29: 44745 | M29: 0.43263889 | N29: Credit card | O29: 8.3162542 | P29: low
A30: 219-61-4139 | B30: C | C30: Chennai | D30: Normal | E30: Male | F30: Electronic accessories | G30: 83.08 | H30: 1 | I30: 4.154 | J30: 0 | K30: 83.08 | L30: 44584 | M30: 0.71944444 | N30: Ewallet | O30: 6.1888404 | P30: low
A31: 318-81-2368 | B31: C | C31: Chennai | D31: Normal | E31: Female | F31: Electronic accessories | G31: 46.2 | H31: 1 | I31: 2.31 | J31: 0 | K31: 46.2 | L31: 44639 | M31: 0.51111111 | N31: Cash | O31: 6.0921397 | P31: low
... A737: 433-08-7822 | B737: C | C737: Chennai | D737: Normal | E737: Female | F737: Health and beauty | G737: 78.89 | H737: 8 | I737: 27.6115 | J737: 0 | K737: 552.23 | L737: 45778 | M737: 0.825 | N737: Ewallet | O737: 7.8022633 | P737: mid
A738: 315-22-5665 | C738: Chennai | D738: Normal | E738: Female | F738: Home and lifestyle | G738: 73.56 | H738: 10 | I738: 36.78 | J738: 772.38 | K738: 735.6 | L738: 43520 | M738: 0.48472222 | N738: Ewallet | O738: 8 | P738: mid
A739: 565-80-5980 | B739: C | C739: Chennai | D739: Member | E739: Female | F739: Home and lifestyle | G739: 47.38 | H739: 4 | I739: 9.476 | J739: 0 | K739: 189.52 | L739: 43488 | M739: 0.43402778 | N739: Cash | O739: 7.1 | P739: mid
A740: 234-65-2137 | B740: C | C740: Chennai | D740: Normal | E740: Male | F740: Home and lifestyle | G740: 95.58 | H740: 10 | I740: 47.79 | J740: 0 | K740: 955.8 | L740: 43481 | M740: 0.56388889 | N740: Cash | O740: 4.8 | P740: mid
A741: 593-65-1552 | B741: C | C741: Chennai | D741: Normal | E741: Female | F741: Home and lifestyle | G741: 69.81 | H741: 4 | I741: 13.962 | J741: 0 | K741: 279.24 | L741: 43493 | M741: 0.86805556 | N741: Credit card | O741: 5.9 | P741: mid
A742: 523-38-0215 | B742: C | C742: Chennai | D742: Normal | E742: Male | F742: Home and lifestyle | G742: 37 | H742: 1 | I742: 1.85 | J742: 0 | K742: 37 | L742: 43619 | M742: 0.56180556 | N742: Credit card | O742: 7.9 | P742: mid
A743: 725-96-3778 | B743: C | C743: Chennai | D743: Member | E743: Female | F743: Home and lifestyle | G743: 89.25 | H743: 8 | I743: 35.7 | J743: 0 | K743: 714 | L743: 43485 | M743: 0.42569444 | N743: Cash | O743: 4.7 | P743: mid
A744: 651-61-0874 | B744: C | C744: Chennai | D744: Normal | E744: Male | F744: Home and lifestyle | G744: 46.22 | H744: 4 | I744: 9.244 | J744: 0 | K744: 184.88 | L744: 43802 | M744: 0.83611111 | N744: Credit card | O744: 6.2 | P744: mid
A745: 767-05-1286 | B745: C | C745: Chennai | D745: Member | E745: Female | F745: Home and lifestyle | G745: 83.77 | H745: 6 | I745: 25.131 | J745: 0 | K745: 502.62 | L745: 43488 | M745: 0.50694444 | N745: Ewallet | O745: 5.4 | P745: mid
...
